Workbook

Sheet Product
A1: รหัสสินค้า | B1: ชื่อสินค้า | C1: หมวดหมู่ | D1: ไฟล์ | E1: สต๊อกเริ่มต้น | F1: สต๊อกขั้นต่ำ | G1: สต๊อกสูงสุด | H1: VS_สต๊อกปัจจุบัน | I1: VS_สถานะสต๊อก
A2: R002701291 | B2: ฝาปิดน้ำมันตัวครอบวงแหวน 5 นิ้ว | C2: b7392108 | D2: Product_Files_/R002701291.ไฟล์.025936.pdf | F2: 0 | G2: 0 | H2: =(SUMIF(Purchases!B:B,A2,Purchases!C:C)-SUMIF(Sales!B:B,A2,Sales!C:C))+E2 -> 0 | I2: =IF(H2 <= 0,"สต๊อกหมด",IF(OR(ISBLANK(F2),F2 <= 0),"สต๊อกเพียงพอ",IF(H2 <= F2,"สต๊อกใกล้หมด","สต๊อกเพียงพอ"))) -> สต๊อกหมด
A3: R002701363 | B3: ฝาปิดน้ำมันตัวครอบวงแหวน 6.5 นิ้ว T22-23 | C3: b7392108 | D3: Product_Files_/R002701363.ไฟล์.030058.5 นิ้ว T22-23 (ใหม่).pdf | F3: 0 | G3: 0 | H3: =(SUMIF(Purchases!B:B,A3,Purchases!C:C)-SUMIF(Sales!B:B,A3,Sales!C:C))+E3 -> 0 | I3: =IF(H3 <= 0,"สต๊อกหมด",IF(OR(ISBLANK(F3),F3 <= 0),"สต๊อกเพียงพอ",IF(H3 <= F3,"สต๊อกใกล้หมด","สต๊อกเพียงพอ"))) -> สต๊อกหมด
A4: R002801741 | B4: ฝาปิดน้ำมัน 2F1 ชุดวงแหวนใหญ่ | C4: b7392108 | D4: Product_Files_/R002801741.ไฟล์.030732.pdf | F4: 0 | G4: 0 | H4: =(SUMIF(Purchases!B:B,A4,Purchases!C:C)-SUMIF(Sales!B:B,A4,Sales!C:C))+E4 -> 0 | I4: =IF(H4 <= 0,"สต๊อกหมด",IF(OR(ISBLANK(F4),F4 <= 0),"สต๊อกเพียงพอ",IF(H4 <= F4,"สต๊อกใกล้หมด","สต๊อกเพียงพอ"))) -> สต๊อกหมด
A5: M005406001 | B5: ตัวครอบวงแหวน 5.5 นิ้ว (T35,T36) สั่งจีน สต๊อกคลัง | C5: b7392108 | D5: Product_Files_/M005406001.ไฟล์.031637.5 นิ้ว 35-36.pdf | F5: 0 | G5: 0 | H5: =(SUMIF(Purchases!B:B,A5,Purchases!C:C)-SUMIF(Sales!B:B,A5,Sales!C:C))+E5 -> 0 | I5: =IF(H5 <= 0,"สต๊อกหมด",IF(OR(ISBLANK(F5),F5 <= 0),"สต๊อกเพียงพอ",IF(H5 <= F5,"สต๊อกใกล้หมด","สต๊อกเพียงพอ"))) -> สต๊อกหมด
A6: Z492965001 | B6: ตัวครอบวงแหวน 4 นิ้ว สั่งจีน สต๊อกคลัง | C6: b7392108 | F6: 0 | G6: 0 | H6: =(SUMIF(Purchases!B:B,A6,Purchases!C:C)-SUMIF(Sales!B:B,A6,Sales!C:C))+E6 -> 0 | I6: =IF(H6 <= 0,"สต๊อกหมด",IF(OR(ISBLANK(F6),F6 <= 0),"สต๊อกเพียงพอ",IF(H6 <= F6,"สต๊อกใกล้หมด","สต๊อกเพียงพอ"))) -> สต๊อกหมด
A7: Z470002078 | B7: ฝาปิดน้ำมัน T1-4,9-10 | C7: b7392108 | F7: 0 | G7: 0 | H7: =(SUMIF(Purchases!B:B,A7,Purchases!C:C)-SUMIF(Sales!B:B,A7,Sales!C:C))+E7 -> 0 | I7: =IF(H7 <= 0,"สต๊อกหมด",IF(OR(ISBLANK(F7),F7 <= 0),"สต๊อกเพียงพอ",IF(H7 <= F7,"สต๊อกใกล้หมด","สต๊อกเพียงพอ"))) -> สต๊อกหมด
A8: R002892192 | B8: เหล็กประกบเพลาขับด้าย 4 นิ้ว | C8: b7392108 | F8: 0 | G8: 0 | H8: =(SUMIF(Purchases!B:B,A8,Purchases!C:C)-SUMIF(Sales!B:B,A8,Sales!C:C))+E8 -> 0 | I8: =IF(H8 <= 0,"สต๊อกหมด",IF(OR(ISBLANK(F8),F8 <= 0),"สต๊อกเพียงพอ",IF(H8 <= F8,"สต๊อกใกล้หมด","สต๊อกเพียงพอ"))) -> สต๊อกหมด
A9: R002703123 | B9: ฝาปิดน้ำมันตัวครอบวงแหวน T17 | C9: b7392108 | F9: 0 | G9: 0 | H9: =(SUMIF(Purchases!B:B,A9,Purchases!C:C)-SUMIF(Sales!B:B,A9,Sales!C:C))+E9 -> 0 | I9: =IF(H9 <= 0,"สต๊อกหมด",IF(OR(ISBLANK(F9),F9 <= 0),"สต๊อกเพียงพอ",IF(H9 <= F9,"สต๊อกใกล้หมด","สต๊อกเพียงพอ"))) -> สต๊อกหมด
A10: R002703120 | B10: ตัวครอบวงแหวน 3.5 นิ้ว T59-60 | C10: b7392108 | F10: 0 | G10: 0 | H10: =(SUMIF(Purchases!B:B,A10,Purchases!C:C)-SUMIF(Sales!B:B,A10,Sales!C:C))+E10 -> 10 | I10: =IF(H10 <= 0,"สต๊อกหมด",IF(OR(ISBLANK(F10),F10 <= 0),"สต๊อกเพียงพอ",IF(H10 <= F10,"สต๊อกใกล้หมด","สต๊อกเพียงพอ"))) -> สต๊อกเพียงพอ
A11: M002702020 | B11: ตัวครอบวงแหวน 6 นิ้ว T11,15 | C11: b7392108 | F11: 0 | G11: 0 | H11: =(SUMIF(Purchases!B:B,A11,Purchases!C:C)-SUMIF(Sales!B:B,A11,Sales!C:C))+E11 -> 0 | I11: =IF(H11 <= 0,"สต๊อกหมด",IF(OR(ISBLANK(F11),F11 <= 0),"สต๊อกเพียงพอ",IF(H11 <= F11,"สต๊อกใกล้หมด","สต๊อกเพียงพอ"))) -> สต๊อกหมด
A12: T000101019 | B12: พลูเล่ย์สายพาน T3-T9-T10(แบบผ่า) | C12: b7392108 | F12: 0 | G12: 0 | H12: =(SUMIF(Purchases!B:B,A12,Purchases!C:C)-SUMIF(Sales!B:B,A12,Sales!C:C))+E12 -> 0 | I12: =IF(H12 <= 0,"สต๊อกหมด",IF(OR(ISBLANK(F12),F12 <= 0),"สต๊อกเพียงพอ",IF(H12 <= F12,"สต๊อกใกล้หมด","สต๊อกเพียงพอ"))) -> สต๊อกหมด
A13: T100300003 | B13: แกนล้อดึงสายพาน 2F1 กลางเครื่อง มีหน้าแปลน | C13: b7392108 | F13: 0 | G13: 0 | H13: =(SUMIF(Purchases!B:B,A13,Purchases!C:C)-SUMIF(Sales!B:B,A13,Sales!C:C))+E13 -> 0 | I13: =IF(H13 <= 0,"สต๊อกหมด",IF(OR(ISBLANK(F13),F13 <= 0),"สต๊อกเพียงพอ",IF(H13 <= F13,"สต๊อกใกล้หมด","สต๊อกเพียงพอ"))) -> สต๊อกหมด
A14: T100300002 | B14: แกนล้อตึงสายพาน 2F1 ชุดบน มีหน้าแปลน | C14: b7392108 | F14: 0 | G14: 0 | H14: =(SUMIF(Purchases!B:B,A14,Purchases!C:C)-SUMIF(Sales!B:B,A14,Sales!C:C))+E14 -> 0 | I14: =IF(H14 <= 0,"สต๊อกหมด",IF(OR(ISBLANK(F14),F14 <= 0),"สต๊อกเพียงพอ",IF(H14 <= F14,"สต๊อกใกล้หมด","สต๊อกเพียงพอ"))) -> สต๊อกหมด
A15: T100300004 | B15: แกนล้อดึงสายพาน 2F1 กลางเครื่อง ไม่มีหน้าแปลน | C15: b7392108 | F15: 0 | G15: 0 | H15: =(SUMIF(Purchases!B:B,A15,Purchases!C:C)-SUMIF(Sales!B:B,A15,Sales!C:C))+E15 -> 0 | I15: =IF(H15 <= 0,"สต๊อกหมด",IF(OR(ISBLANK(F15),F15 <= 0),"สต๊อกเพียงพอ",IF(H15 <= F15,"สต๊อกใกล้หมด","สต๊อกเพียงพอ"))) -> สต๊อกหมด
A16: R002819018 | B16: ล้อดึงสายพาน(วงแหวน) สต๊อกคลัง | C16: b7392108 | F16: 0 | G16: 0 | H16: =(SUMIF(Purchases!B:B,A16,Purchases!C:C)-SUMIF(Sales!B:B,A16,Sales!C:C))+E16 -> 17 | I16: =IF(H16 <= 0,"สต๊อกหมด",IF(OR(ISBLANK(F16),F16 <= 0),"สต๊อกเพียงพอ",IF(H16 <= F16,"สต๊อกใกล้หมด","สต๊อกเพียงพอ"))) -> สต๊อกเพียงพอ
A17: R002703032 | B17: สลักล้อดึงสายพาน(วงแหวน) | C17: b7392108 | F17: 0 | G17: 0 | H17: =(SUMIF(Purchases!B:B,A17,Purchases!C:C)-SUMIF(Sales!B:B,A17,Sales!C:C))+E17 -> 5 | I17: =IF(H17 <= 0,"สต๊อกหมด",IF(OR(ISBLANK(F17),F17 <= 0),"สต๊อกเพียงพอ",IF(H17 <= F17,"สต๊อกใกล้หมด","สต๊อกเพียงพอ"))) -> สต๊อกเพียงพอ
A18: 1111111111 | B18: ตัวครอบวงแหวน 8นิ้ว | C18: b7392108 | E18: 0 | F18: 2 | G18: 5 | H18: =(SUMIF(Purchases!B:B,A18,Purchases!C:C)-SUMIF(Sales!B:B,A18,Sales!C:C))+E18 -> 13 | I18: =IF(H18 <= 0,"สต๊อกหมด",IF(OR(ISBLANK(F18),F18 <= 0),"สต๊อกเพียงพอ",IF(H18 <= F18,"สต๊อกใกล้หมด","สต๊อกเพียงพอ"))) -> สต๊อกเพียงพอ
A19: R002703033 | B19: ตัวครอบวงแหวน 10 นิ้ว ( T50,51 ) | C19: b7392108 | F19: 2 | G19: 5 | H19: =(SUMIF(Purchases!B:B,A19,Purchases!C:C)-SUMIF(Sales!B:B,A19,Sales!C:C))+E19 -> 4 | I19: =IF(H19 <= 0,"สต๊อกหมด",IF(OR(ISBLANK(F19),F19 <= 0),"สต๊อกเพียงพอ",IF(H19 <= F19,"สต๊อกใกล้หมด","สต๊อกเพียงพอ"))) -> สต๊อกเพียงพอ
A20: 11 | B20: ลูกกลิ้งทับใย 4" | C20: b453465a | F20: 50 | G20: 100 | H20: =(SUMIF(Purchases!B:B,A20,Purchases!C:C)-SUMIF(Sales!B:B,A20,Sales!C:C))+E20 -> 135 | I20: =IF(H20 <= 0,"สต๊อกหมด",IF(OR(ISBLANK(F20),F20 <= 0),"สต๊อกเพียงพอ",IF(H20 <= F20,"สต๊อกใกล้หมด","สต๊อกเพียงพอ"))) -> สต๊อกเพียงพอ
A21: 0 | B21: ตัวครอบวงแหว 5" | C21: b7392108 | F21: 5 | G21: 10 | H21: =(SUMIF(Purchases!B:B,A21,Purchases!C:C)-SUMIF(Sales!B:B,A21,Sales!C:C))+E21 -> 27 | I21: =IF(H21 <= 0,"สต๊อกหมด",IF(OR(ISBLANK(F21),F21 <= 0),"สต๊อกเพียงพอ",IF(H21 <= F21,"สต๊อกใกล้หมด","สต๊อกเพียงพอ"))) -> สต๊อกเพียงพอ
A22: 1 | B22: ต้วครอบวงแหวน 4 1/2" ( T24 ) | C22: b7392108 | F22: 3 | G22: 10 | H22: =(SUMIF(Purchases!B:B,A22,Purchases!C:C)-SUMIF(Sales!B:B,A22,Sales!C:C))+E22 -> 4 | I22: =IF(H22 <= 0,"สต๊อกหมด",IF(OR(ISBLANK(F22),F22 <= 0),"สต๊อกเพียงพอ",IF(H22 <= F22,"สต๊อกใกล้หมด","สต๊อกเพียงพอ"))) -> สต๊อกเพียงพอ
A23: 2 | B23: ตัวครอบวงแหวน 6 1/2" ( T22,23 ) | C23: b7392108 | F23: 3 | G23: 10 | H23: =(SUMIF(Purchases!B:B,A23,Purchases!C:C)-SUMIF(Sales!B:B,A23,Sales!C:C))+E23 -> 21 | I23: =IF(H23 <= 0,"สต๊อกหมด",IF(OR(ISBLANK(F23),F23 <= 0),"สต๊อกเพียงพอ",IF(H23 <= F23,"สต๊อกใกล้หมด","สต๊อกเพียงพอ"))) -> สต๊อกเพียงพอ
A24: 3 | B24: ต้วครอบวงแหวน 7" (T21) | C24: b7392108 | F24: 2 | G24: 5 | H24: =(SUMIF(Purchases!B:B,A24,Purchases!C:C)-SUMIF(Sales!B:B,A24,Sales!C:C))+E24 -> 4 | I24: =IF(H24 <= 0,"สต๊อกหมด",IF(OR(ISBLANK(F24),F24 <= 0),"สต๊อกเพียงพอ",IF(H24 <= F24,"สต๊อกใกล้หมด","สต๊อกเพียงพอ"))) -> สต๊อกเพียงพอ
A25: 4 | B25: ต้วครอบวงแหวน 10" ( T18 ) | C25: b7392108 | F25: 3 | G25: 5 | H25: =(SUMIF(Purchases!B:B,A25,Purchases!C:C)-SUMIF(Sales!B:B,A25,Sales!C:C))+E25 -> 8 | I25: =IF(H25 <= 0,"สต๊อกหมด",IF(OR(ISBLANK(F25),F25 <= 0),"สต๊อกเพียงพอ",IF(H25 <= F25,"สต๊อกใกล้หมด","สต๊อกเพียงพอ"))) -> สต๊อกเพียงพอ
A26: 5 | B26: วงแหวน 3"1/2 ( T59,60 ) | C26: b7392108 | F26: 3 | G26: 5 | H26: =(SUMIF(Purchases!B:B,A26,Purchases!C:C)-SUMIF(Sales!B:B,A26,Sales!C:C))+E26 -> 10 | I26: =IF(H26 <= 0,"สต๊อกหมด",IF(OR(ISBLANK(F26),F26 <= 0),"สต๊อกเพียงพอ",IF(H26 <= F26,"สต๊อกใกล้หมด","สต๊อกเพียงพอ"))) -> สต๊อกเพียงพอ
A27: 6 | B27: วงแหวน 4" ( T3,9,34 ) | C27: b7392108 | F27: 3 | G27: 10 | H27: =(SUMIF(Purchases!B:B,A27,Purchases!C:C)-SUMIF(Sales!B:B,A27,Sales!C:C))+E27 -> 36 | I27: =IF(H27 <= 0,"สต๊อกหมด",IF(OR(ISBLANK(F27),F27 <= 0),"สต๊อกเพียงพอ",IF(H27 <= F27,"สต๊อกใกล้หมด","สต๊อกเพียงพอ"))) -> สต๊อกเพียงพอ
A28: 7 | B28: วงแหวน 4"1/2 (T25 ) | C28: b7392108 | F28: 3 | G28: 5 | H28: =(SUMIF(Purchases!B:B,A28,Purchases!C:C)-SUMIF(Sales!B:B,A28,Sales!C:C))+E28 -> 58 | I28: =IF(H28 <= 0,"สต๊อกหมด",IF(OR(ISBLANK(F28),F28 <= 0),"สต๊อกเพียงพอ",IF(H28 <= F28,"สต๊อกใกล้หมด","สต๊อกเพียงพอ"))) -> สต๊อกเพียงพอ
A29: 8 | B29: วงแหวน 5" ( T6,7,8,13,14 ) | C29: b7392108 | F29: 3 | G29: 10 | H29: =(SUMIF(Purchases!B:B,A29,Purchases!C:C)-SUMIF(Sales!B:B,A29,Sales!C:C))+E29 -> 160 | I29: =IF(H29 <= 0,"สต๊อกหมด",IF(OR(ISBLANK(F29),F29 <= 0),"สต๊อกเพียงพอ",IF(H29 <= F29,"สต๊อกใกล้หมด","สต๊อกเพียงพอ"))) -> สต๊อกเพียงพอ
A30: 9 | B30: วงแหวน 5"1/2 (T35,36,57,58) | C30: b7392108 | F30: 3 | G30: 10 | H30: =(SUMIF(Purchases!B:B,A30,Purchases!C:C)-SUMIF(Sales!B:B,A30,Sales!C:C))+E30 -> 6 | I30: =IF(H30 <= 0,"สต๊อกหมด",IF(OR(ISBLANK(F30),F30 <= 0),"สต๊อกเพียงพอ",IF(H30 <= F30,"สต๊อกใกล้หมด","สต๊อกเพียงพอ"))) -> สต๊อกเพียงพอ
... A82: 20 | B82: วงแหวน 5"1/2 (T61,62) | C82: b7392108 | F82: 5 | G82: 10 | H82: =(SUMIF(Purchases!B:B,A82,Purchases!C:C)-SUMIF(Sales!B:B,A82,Sales!C:C))+E82 -> 6 | I82: =IF(H82 <= 0,"สต๊อกหมด",IF(OR(ISBLANK(F82),F82 <= 0),"สต๊อกเพียงพอ",IF(H82 <= F82,"สต๊อกใกล้หมด","สต๊อกเพียงพอ"))) -> สต๊อกเพียงพอ

Sheet Sales
A1: วันที่/เวลา | B1: รหัสสินค้า | C1: จำนวน | D1: ผู้ทำรายการ | E1: หมายเหตุ/รายละเอียด
A2: 45239.345 | B2: 0226046501 | C2: 1 | D2: ยศศักดิ์
A3: 45239.346 | B3: 022604AT01 | C3: 1 | D3: ยศศักดิ์
A4: 45246.439 | B4: 0226141304 | C4: 1 | D4: ยศศักดิ์
A5: 45246.439 | B5: 0226141601 | C5: 1 | D5: ยศศักดิ์
A6: 45246.59 | B6: 022614BH01 | C6: 1 | D6: ยศศักดิ์ | E6: K49
A7: 45245.449 | B7: 0226142101 | C7: 1 | D7: ยศศักดิ์ | E7: สายพานบน
A8: 45248.563 | B8: 022614BH01 | C8: 1 | D8: ยศศักดิ์ | E8: K44
A9: 45250.366 | B9: 0226045501 | C9: 1 | D9: ยศศักดิ์ | E9: K49
A10: 45253.361 | B10: 022614BH01 | C10: 1 | D10: ยศศักดิ์ | E10: ใส่เครื่อง65ล่าง
A11: 45257.351 | B11: 022614BD02 | C11: 1 | D11: ยศศักดิ์ | E11: K32
A12: 45261.589 | B12: 0226142101 | C12: 1 | D12: ยศศักดิ์ | E12: ใส่k56
A13: 45265.286 | B13: 022614BH01 | C13: 1 | D13: ยศศักดิ์ | E13: K44
A14: 45265.664 | B14: 0226045501 | C14: 1 | D14: ยศศักดิ์
A15: 45281.558 | B15: 0226045501 | C15: 1 | D15: ยศศักดิ์ | E15: ใส่k49
A16: 45286.58 | B16: 0226147501 | C16: 25 | D16: ยศศักดิ์
A17: 45286.582 | B17: 0226147501 | C17: 5 | D17: ยศศักดิ์
A18: 45295.294 | B18: 0226045501 | C18: 1 | D18: ยศศักดิ์ | E18: ใส่k49
A19: 45299.614 | B19: 022614BD02 | C19: 1 | D19: ยศศักดิ์ | E19: K26 ใส่เส้นใหม่
A20: 45300.485 | B20: 022614BH01 | C20: 3 | D20: ยศศักดิ์ | E20: K56 k47 k44
A21: 45300.486 | B21: 0226147501 | C21: 20 | D21: ยศศักดิ์
A22: 45301.449 | B22: 0226045501 | C22: 1 | D22: ยศศักดิ์ | E22: ใส่k49 วันที่ 9/1/67
A23: 45307.407 | B23: 0226147501 | C23: 30 | D23: ยศศักดิ์ | E23: ใส่k23 22 21
A24: 45309.368 | B24: 022614BH01 | C24: 1 | D24: ยศศักดิ์
A25: 45309.475 | B25: 0226147501 | C25: 20 | D25: ยศศักดิ์ | E25: ใส่k5
A26: 45309.756 | B26: 022614BH01 | C26: 1 | D26: ยศศักดิ์
A27: 45309.757 | B27: 022614BD01 | C27: 1 | D27: ยศศักดิ์ | E27: ใส่k3
A28: 45309.757 | B28: 022614BD02 | C28: 1 | D28: ยศศักดิ์ | E28: ใส่k29
A29: 45310.454 | B29: 022614BH01 | C29: 1 | D29: ยศศักดิ์ | E29: ใส่k55
A30: 45310.456 | B30: 0226147501 | C30: 10 | D30: ยศศักดิ์
A31: 45313.783 | B31: 0226142401 | C31: 1 | D31: ยศศักดิ์ | E31: ใส่W6
A32: 45329.36 | B32: 022614BD02 | C32: 1 | D32: ยศศักดิ์ | E32: ใส่k31
A33: 45331.437 | B33: 022614BH01 | C33: 2 | D33: ยศศักดิ์
A34: 45332.448 | B34: 022614BD02 | C34: 1 | D34: ยศศักดิ์ | E34: ใส่k33
A35: 45334.449 | B35: 0226147501 | C35: 2 | D35: ยศศักดิ์
A36: 45334.452 | B36: 0226142401 | C36: 1 | D36: ยศศักดิ์
A37: 45343.543 | B37: 022614BH01 | C37: 1 | D37: ยศศักดิ์ | E37: ใส่k54
A38: 45344.734 | B38: 0226142201 | C38: 1 | D38: ยศศักดิ์
A39: 45345.369 | B39: 022614BH01 | C39: 1 | D39: ยศศักดิ์ | E39: ใส่k44
A40: 45346.356 | B40: 022614BD02 | C40: 1 | D40: ยศศักดิ์ | E40: ใส่k34
...

Sheet Purchases
A1: วันที่/เวลา | B1: รหัสสินค้า | C1: จำนวน | D1: ผู้ทำรายการ | E1: หมายเหตุ/รายละเอียด
A2: 45246.432 | C2: 2 | D2: ยศศักดิ์
A3: 45246.433 | B3: 022604AT01 | C3: 2 | D3: ยศศักดิ์
A4: 45246.436 | B4: 0226142101 | C4: 1 | D4: ยศศักดิ์
A5: 45246.437 | B5: 022614BH01 | C5: 1 | D5: ยศศักดิ์
A6: 45246.438 | B6: 022614BD02 | C6: 3 | D6: ยศศักดิ์
A7: 45246.438 | B7: 022614BD01 | C7: 1 | D7: ยศศักดิ์
A8: 45265.683 | B8: 022614BD02 | C8: 5 | D8: ยศศักดิ์ | E8: เครื่องเกาหลี
A9: 45266.421 | B9: 0226142201 | C9: 2 | D9: ยศศักดิ์
A10: 45275.435 | B10: 0226045501 | C10: 3 | D10: ยศศักดิ์ | E10: 15/12/66
A11: 45275.436 | B11: 0226046501 | C11: 2 | D11: ยศศักดิ์ | E11: 15/12/66
A12: 45286.58 | B12: 0226147501 | C12: 100 | D12: ยศศักดิ์
A13: 45286.583 | B13: 0226147501 | C13: 5 | D13: ยศศักดิ์
A14: 45300.485 | B14: 022614BH01 | C14: 5 | D14: ยศศักดิ์
A15: 45301.449 | B15: 0226045501 | C15: 2 | D15: ยศศักดิ์
A16: 45309.758 | B16: 022614BH01 | C16: 1 | D16: ยศศักดิ์
A17: 45327.604 | C17: 1 | D17: ยศศักดิ์
A18: 45327.605 | B18: 0226142401 | C18: 1 | D18: ยศศักดิ์
A19: 45327.606 | B19: 0226147501 | C19: 2 | D19: ยศศักดิ์ | E19: สต๊อคหน้างานอยู่กับช่างเทคนิค
A20: 45327.417 | B20: 0226142401 | C20: 1 | D20: ยศศักดิ์ | E20: 3/2/67
A21: 45330.708 | B21: 022614BH01 | C21: 1 | D21: ยศศักดิ์
A22: 45331.433 | B22: 022614BH01 | C22: 1 | D22: ยศศักดิ์
A23: 45336.56 | B23: 022614BH01 | C23: 5 | D23: ยศศักดิ์
A24: 45385.432 | B24: 0226142401 | C24: 1 | D24: ยศศักดิ์
A25: 45386.431 | B25: 022614BH01 | C25: 5 | D25: ยศศักดิ์
A26: 45390.481 | B26: 022614BD01 | C26: 3 | D26: ยศศักดิ์
A27: 45407.374 | B27: 0226046501 | C27: 1 | D27: ยศศักดิ์
A28: 45407.375 | B28: 0226142401 | C28: 1 | D28: ยศศักดิ์
A29: 45416.648 | B29: 0226142101 | C29: 1 | D29: ยศศักดิ์
A30: 45418.648 | B30: 0226147501 | C30: 300 | D30: ยศศักดิ์
A31: 45425.639 | B31: 022614BH01 | C31: 5 | D31: ยศศักดิ์
A32: 45436.457 | B32: 0226045501 | C32: 1 | D32: ยศศักดิ์
... A36: 45440.624 | B36: 0226142401 | C36: 1 | D36: ยศศักดิ์
A37: 45449.369 | B37: 022614BH01 | C37: 1 | D37: ยศศักดิ์ | E37: ของเก่าk49
A38: 45462.426 | B38: 022614BD02 | C38: 5 | D38: ยศศักดิ์
A39: 45462.427 | B39: 022614BH01 | C39: 1 | D39: ยศศักดิ์
A40: 45472.348 | B40: 022614BH01 | C40: 5 | D40: ยศศักดิ์
A41: 45475.413 | B41: 0226045501 | C41: 1 | D41: ยศศักดิ์
A42: 45495.532 | B42: 0226142101 | C42: 1 | D42: ยศศักดิ์
A43: 45495.65 | B43: 0226142201 | C43: 1 | D43: ยศศักดิ์ | E43: ของเก่าk49
...

Sheet SettingGroup
A1: รหัสหมวดหมู่ | B1: หมวดหมู่
A2: b7392108 | B2: อะไหล่
A3: b453465a | B3: อะไหล่เวียน

Sheet SettingUser
A1: ID | B1: UserName
A2: d1edb8ee | B2: พนักงาน 1
A3: db4d3990 | B3: พนักงาน 2
A4: 1f13629c | B4: พนักงาน 3

Sheet Filters
A1: ID | B1: สถานะสต๊อก | C1: นำออกรายงาน
A2: 7b07473b | B2: สต๊อกเพียงพอ,สต๊อกใกล้หมด,สต๊อกหมด,สต๊อกเกินกำหนด | C2: TRUE

Sheet Dashboard
A1: สรุปสถานะสต๊อก
A2: วันที่ | B2: =text(today(),"dd/mm/yyyy") -> 03/09/2026
A3: สต๊อกเพียงพอ | B3: =COUNTIF(Product!I:I,A3) -> 56
A4: สต๊อกใกล้หมด | B4: =COUNTIF(Product!I:I,A4) -> 11
A5: สต๊อกหมด | B5: =COUNTIF(Product!I:I,A5) -> 14
A6: สต๊อกเกินกำหนด | B6: =COUNTIF(Product!I:I,A6) -> 0
